Workbook
Name _Key1: [2]ALL!#REF!
Name _Order1: 255
Name _Order2: 1
Name A_1: [1]ALL!#REF!
Name A_2: [1]ALL!#REF!
Name A_3: [1]ALL!#REF!
Name AR: [1]ALL!#REF!
Name B_1: [1]ALL!#REF!
Name B_2: [1]ALL!#REF!
Name B_3: [1]ALL!#REF!
Name CNT: [1]ALL!#REF!
Name Convert: '[3]（入力シート）A-2-①'!$AH$4
Name END_M: [1]ALL!#REF!
Name FLAG: [1]ALL!#REF!
Name INSERT_1: [1]ALL!#REF!
Name INSERT_2: [1]ALL!#REF!
Name LX: [1]ALL!#REF!
Name MACRO: [1]ALL!#REF!
Name MEM_WID: [1]ALL!#REF!
Name MENU_R_D: [1]ALL!#REF!
Name MENU_R_E: [1]ALL!#REF!
Name MENU_R_I: [1]ALL!#REF!
Name MENU_R_P: [1]ALL!#REF!
Name MENU_R_PP: [1]ALL!#REF!
Name MENU_R_S: [1]ALL!#REF!
Name MENU_S: [1]ALL!#REF!
Name MENU_S_M: [1]ALL!#REF!
Name monthName: [4]Settings!$G$12
Name OLE_LINK1: ' 出貨派車單'!#REF!
Name OPLINE_2: [5]UK!#REF!
Name RCW_1: [1]ALL!#REF!
Name REC_WID: [1]ALL!#REF!
Name START_M: [1]ALL!#REF!
Name SX: [1]ALL!#REF!
Name SY: [1]ALL!#REF!
Name WID_0: [1]ALL!#REF!
Name WID_1: [1]ALL!#REF!
Name WID_2: [1]ALL!#REF!
Name WID_LINE: [1]ALL!#REF!
Name WIDE_P: [2]ALL!#REF!
Name year: [6]工作表1!#REF!
Name 工程: [7]工程!$C$3:$C$33
Name 区分: [7]区分!$C$3:$C$32
Name 受注推移2014: [1]ALL!#REF!
Name 設備: [7]設備!$C$3:$D$53
Name 設備番号: [7]設備!$C$3:$C$53
Name 類別: '[8]2022.1~2023.8月'!$A$2:$A$10
Name PRINT_AREA_MI1: #REF!
Name 東京出荷: #REF!
Name _Z2: #REF!
Name ___KU9: #REF!
Name _______KU2: #REF!
Name aaa: #REF!
Name GBP: #REF!
Name _KU2: #REF!
Name ____KU1: #REF!
Name _______KU8: #REF!
Name ________KU1: #REF!
Name GGG: #REF!
Name 重機ﾚﾝﾀﾙ: #REF!

Sheet 新規案件追踪
A1: 報表製作日: | B1: 46210 | F1: 機械 | G1: 制御 | H1: 生產 | I1: 生產 | J1: 生產 | K1: 生產 | L1: 生產 | M1: 生產 | N1: 生產 | O1: 生產 | P1: 製造 | Q1: 制御或製造 | R1: 生產倉庫 | S1: 營業 | T1: ?代表尚未建立出貨通知 | X1: 生產
A2: PJ號碼 | B2: 客戶 | C2: 工事名稱/EFEM TYPE | D2: 業種 | E2: 組立地點 | F2: 機械出圖日 | G2: 制御出圖日 | H2: 機械集合日 | I2: Harness、制御盤 集合日 | J2: Robot X番號 | K2: Robot 予入日 | L2: Load port 仕樣 | M2: Load port 予入日 | N2: Alinger 仕樣 | O2: Alinger 予入日 | P2: 製造 組立完成日 | Q2: 制御測試完成日 | R2: 梱包日 | S2: Customer Target(M/I Date) | T2: M/I Time | U2: 設計擔當 | V2: 制御擔當 | W2: 營業擔當 | X2: M/I 完成
A3: 55-02157 | B3: 晶彩 | C3: KWE300-2P-FO-AL for FAVITE | D3: 新規 | E3: 平田 | F3: 46112 | G3: 46106 | H3: 46204 | I3: 46204 | J3: X413 | K3: 46191 | L3: L325 | M3: 46175 | N3: A003 | O3: 46204 | P3: 46234 | Q3: 46236 | R3: 46237 | S3: 46218 | T3: ? | U3: Amos | V3: Hardy | W3: Joyce
A4: 55-02300 | B4: PTI | C4: 510*515 2P Panel EFEM for 佳宸 | D4: 新規 | E4: 平田 | F4: 46163 | G4: 46194 | H4: 46211 | I4: 46225 | J4: SP006 | K4: 46197 | L4: FL002 | M4: 46203 | N4: N/A | O4: N/A | P4: 46239 | S4: 46241 | T4: ? | U4: Roy | V4: Dar | W4: Eason
A5: 55-01867 | B5: S1 | C5: KWS300-TS003, 4LP Sorter | D5: 新規 | E5: 群瑞 | F5: H01523-ST-W-01A | G5: H01523-ST-W-01A | H5: 46127 | I5: 46135 | J5: X564 | L5: L723 | N5: A099 | S5: 46203 | T5: ? | U5: David | V5: Hardy | W5: Jeffrey
A6: 55-01803 | B6: CMIT 政美 | C6: Load Port KWF-12F3-8M-RFID-QUARTZ1-INFO1_10sets | D6: Componets | E6: 平田 | F6: 46097 | G6: 46098 | H6: 46162 | I6: 46162 | J6: N/A | K6: N/A | L6: L705 | M6: 46197 | N6: N/A | O6: N/A
A7: 55-02467 | B7: GPM | C7: 台中GPM KWE300-2P-FO-AL for AOI 檢查機 | D7: 新規 | E7: 平田 | F7: 46203 | G7: 46203 | H7: 46249 | I7: 46249 | P7: 46262 | R7: 46263 | S7: 46264
A8: 55-02308-01 | B8: HCJ | C8: 300X EFEM LOT 54 | D8: 新規 | E8: 平田 | F8: 46172 | G8: N/A | H8: 46244 | I8: N/A
A9: 55-02406 | B9: TKK | C9: ASECL KWE300-2P-FO-AL for Asmytek 1對4 | D9: 新規 | E9: 平田 | F9: 46210 | G9: 46220 | H9: 46309 | I9: 46309 | J9: X413 | L9: L614 | N9: A036 | P9: 46262 | R9: 46263 | S9: 46264 | U9: longer | V9: Hardy | W9: Jeffrey
A12: 表頭皆是可在引繼會議上產出。 | E12: 1.裝置組立地點,在引繼會議時,即可得知 2.要可修改功能 | F12: 1.機械人員,BOM表出圖日,也是作業完成日 規則1引繼會議上的日期是白底黑字 規則2.機械人員搜尋專案工事,作業完成KEY上去日期按上確認。呈現灰底黑字(在引繼日期內) 規則3.超出規則1的日期時,有更新日期會呈現白底紅字的新日期 規則4.超出規則1的日期時,無更新日期會呈現規則1的紛底紅字日期 規則5.依次類推,有可能已更新的日期,還無法達成,繼續走規則3~4。 | G12: 1.制御人員,BOM表出圖日,也是作業完成日 規則1引繼會議上的日期是白底黑字 規則2.制御人員搜尋專案工事,作業完成KEY上去日期按上確認。呈現灰底黑字(在引繼日期內) 規則3.超出規則1的日期時,有更新日期會呈現白底紅字的新日期 規則4.超出規則1的日期時,無更新日期會呈現規則1的紛底紅字日期 規則5.依次類推,有可能已更新的日期,還無法達成,繼續走規則3~4。 | H12: 1.生產買料的物料到料時間。一段式作業 2.物料的內容主要是供應商作好,即送到平田/群瑞 規則1.引繼會議上的日期是白底黑字 規則2.料管人員搜尋專案工事,作業完成KEY上去日期按上確認。呈現灰底黑字(在引繼日期內) 規則3.超出規則1的日期時,有更新日期會呈現白底紅字的新日期 規則4.超出規則1的日期時,無更新日期會呈現規則1的紛底紅字日期 規則5.依次類推,有可能已更新的日期,還無法達成,繼續走規則3~4。 | I12: 1.生產買料的物料到料時間。二段式 2.物料的內容主要是供應商作好,還要送到加工商, 加工商作好再送到平田/群瑞 規則1.引繼會議上的日期是白底黑字 規則2.料管人員搜尋專案工事,作業完成KEY上去日期按上確認。呈現灰底黑字(在引繼日期內) 規則3.超出規則1的日期時,有更新日期會呈現白底紅字的新日期 規則4.超出規則1的日期時,無更新日期會呈現規則1的紛底紅字日期 規則5.依次類推,有可能已更新的日期,還無法達成,繼續走規則3~4。 | J12: ROBOT 仕樣 | K12: ROBOT預進貨日期在引繼會議上放入的日期 規則1引繼會議上的日期是白底灰字 規則2.採購有明細的日期時會呈現白底黑字 規則3.倉庫發料後,登錄作業時間.按確認,呈現灰底黑字 規則4.超出日期規則2時,有更新日期會呈現白底紅字的日期 規則5.超出日期規則2時,無更新日期會呈現規則2的紛底紅字日期 | L12: Load port 仕樣 前面日期作業完成後,連同一起呈現灰底黑字 | M12: Load port預進貨日期在引繼會議上放入的日期 規則1引繼會議上的日期是白底灰字 規則2.採購有明細的日期時會呈現白底黑字 規則3.倉庫發料後,登錄作業時間.按確認,呈現灰底黑字 規則4.超出日期規則2時,有更新日期會呈現白底紅字的日期 規則5.超出日期規則2時,無更新日期會呈現規則2的紛底紅字日期 | N12: Alinger 仕樣 前面日期作業完成後,連同一起呈現灰底黑字 | O12: Alinger預進貨日期在引繼會議上放入的日期 規則1引繼會議上的日期是白底灰字 規則2.採購有明細的日期時會呈現白底黑字 規則3.倉庫發料後,登錄作業時間.按確認,呈現灰底黑字 規則4.超出日期規則2時,有更新日期會呈現白底紅字的日期 規則5.超出日期規則2時,無更新日期會呈現規則2的紛底紅字日期 | P12: 機台組立完成的時間 規則1.引繼會議上的日期是白底黑字 規則2.製造人員搜尋專案工事,作業完成KEY上去日期按上確認。呈現灰底黑字(在引繼日期內) 規則3.超出規則1的日期時,有更新日期會呈現白底紅字的新日期 規則4.超出規則1的日期時,無更新日期會呈現規則1的紛底紅字日期 規則5.依次類推,有可能已更新的日期,還無法達成,繼續走規則3~4。 | Q12: 機台test完成的時間 規則1.引繼會議上的日期是白底黑字 規則2.制御人員搜尋專案工事,作業完成KEY上去日期按上確認。呈現灰底黑字(在引繼日期內) 規則3.超出規則1的日期時,有更新日期會呈現白底紅字的新日期 規則4.超出規則1的日期時,無更新日期會呈現規則1的紛底紅字日期 規則5.依次類推,有可能已更新的日期,還無法達成,繼續走規則3~4。 | R12: 機台梱包完成的時間 規則1.引繼會議上的日期是白底黑字 規則2.生產倉庫人員搜尋專案工事,作業完成KEY上去日期按上確認。呈現灰底黑字(在引繼日期內) 規則3.超出規則1的日期時,有更新日期會呈現白底紅字的新日期 規則4.超出規則1的日期時,無更新日期會呈現規則1的紛底紅字日期 規則5.依次類推,有可能已更新的日期,還無法達成,繼續走規則3~4。 | S12: 機台M/I予定日 規則1.引繼會議上的日期是白底黑字 規則2.營業要變更日期,呈現是綠底紅字 規則3.欄位F.G.H.I.K.M.N.O.P.Q.R.若都沒完成,要重新開立引繼會議。 規則4.規則2.欄位H~若都沒完成,要重新開立引繼會議。 規則5.欄位P~沒完成,則在會議上,討論後,請各欄位負責人重新壓更新的日期即可。 | T12: 負責人員:營業 | U12: 在引繼會議時,即可得知 主要為專案工事負責的窗口 | V12: 在引繼會議時,即可得知 主要為專案工事負責的窗口 | W12: 在引繼會議時,即可得知 主要為專案工事負責的窗口 | X12: 負責人員:生產
E13: 負責人員:製造/生產 | F13: 負責人員:機械 | G13: 負責人員:制御 | H13: 負責人員:生產 | I13: 負責人員:生產 | J13: 負責人員:生產 | K13: 負責人員:生產(採購/倉庫) | L13: 負責人員:生產 | M13: 負責人員:生產(採購/倉庫) | N13: 負責人員:生產 | O13: 負責人員:生產(採購/倉庫) | P13: 組立地點在平田時,負責單位製造部 | Q13: 組立地點在平田時,負責單位制御部 | R13: 負責人員:生產 | S13: 1.營業有變更時間 | T13: 1.營業有客戶的出貨時間
F14: 工號/英文名 | G14: 工號/英文名 | H14: 工號/英文名 | I14: 工號/英文名 | J14: 這個欄位要可以修改 | K14: 工號/英文名 | L14: 這個欄位要可以修改 | N14: 這個欄位要可以修改 | P14: 組立地點非平田時,負責單位製造部 | Q14: 組立地點非平田時,負責單位製造部 | T14: 2.填寫出貨通知單+Packing List (要能夾附件檔) *能由系統發出出貨通知信件給相關部門
A15: PS. 1.作業完成確認日期，只能當日 2.作業延期日期,只能往後。 3.專案工事Pending時要在那邊作確認 規則1.工事暫時追踪,營業課級主管MAILL連絡後, 規則2.生產PJ主持人,會去按Pending或cancel,整列要作粉底黑字。 規則3.工事重啟,營業窗口要maill連絡並開立引繼會議通知,生產PJ主持人,會去按重啟 規則4.開立完引繼會議後,相關日程重新開始追蹤。 | F15: 用工號登入,即產生英文名 | J15: 是依照我想要修改方式呈現。 | K15: N/A來源在引繼會議上時即填入 | L15: 是依照我想要修改方式呈現。 | M15: N/A來源在引繼會議上時即填入 | N15: 是依照我想要修改方式呈現。 | O15: N/A來源在引繼會議上時即填入 | P15: 工號/英文名
F16: ex.輸入 | J16: Ex. | L16: N/A來源在引繼會議上時即填入 | M16: 負責人員: | N16: N/A來源在引繼會議上時即填入
F17: 工號:1077 | J17: X162->X413 | L17: 工號/英文名 | M17: 工號/英文名 | N17: 工號/英文名 | O17: 工號/英文名
F18: 英文:Longer | J18: SP004->SP006
F19: 後續會提供,該欄位 | J19: 客供
F20: 可以key in的名單 | J20: …等不限制我要改的內容
J21: 負責人員:
J22: 工號/英文名
J23: N/A來源在引繼會議上時即填入

Sheet 派車單--資料寫入
A1: 項目 | B1: 資料寫入欄
A2: 專案代號 | B2: 55-02137
A3: 製作專案
A4: 番号Type
A5: 荏原製番 | C5: \\192.168.1.110\04_Project\★1 HCT 300X Order Schedule管理表\營業\300X 仕様聯絡資料\H2-xxxx | I5: 台灣平田機工(股)公司 | J5: 桃園縣新屋鄉新華路一段128號
A6: 裝車日期 | B6: 46212 | I6: 友達光電股份有限公司(L5D) | J6: 桃園縣龜山鄉華亞二路189號（華亞園區）
A7: 裝車時間 | B7: 0.70833333 | I7: 友達光電股份有限公司 | J7: 新竹市科學工業園區力行二路1號
A8: 裝車地點 | B8: 桃園市中壢區福祥路298-1號 | I8: 友達光電股份有限公司龍科 (L6B 廠 / C6B 廠 / M02 廠) | J8: 32542 桃園縣龍潭鄉龍科街228號 (友達光電龍科廠)
A9: 裝車名稱 | B9: 台灣平田機工(股)公司 | I9: 友達光電股份有限公司 | J9: 台中市中部科學園區中科路1號
A10: 到貨日期 | B10: 46213 | I10: 群創光電股份有限公司 | J10: 苗栗縣竹南鎮科學路160號
A11: 到貨時間 | B11: 0.4375 | I11: 台灣芝浦先進科技股份有限公司 | J11: 新竹市信義街68號9樓
A12: 到貨地點 | B12: 台灣積體電路製造股份有限公司 AP8 台南市新市區環西路一段3號 | I12: 東京威力科創股份有限公司 | J12: 新竹市埔頂路18號7樓
A13: 客戶名稱 | B13: 台灣積體電路製造股份有限公司 | I13: 台灣凸版國際彩光股份有限公司 | J13: 709 台南市安南區科技一路36號（台南科技工業區）
A14: 客戶簽收人 | B14: AP8 劉韋智 | I14: 台灣荏原精密股份有限公司 | J14: 303 新竹縣湖口鄉新竹工業區自強路5號
A15: 客戶簽收電話 | B15: #7553278 | I15: 台灣積體電路製造股份有限公司 (FB30庫房) | J15: 桃園市龍潭區龍園六路101號(北側)
A16: 車輛種類 | B16: 310cm 低板 | I16: 台灣積體電路製造股份有限公司(6號碼頭) | J16: 桃園市龍潭區龍園六路101號
A17: 車輛數 | B17: 共1輛 | I17: 台灣積體電路製造股份有限公司 | J17: 新竹科學園區力行三路 (Tsmc12 P6 move in 口)
A18: 接貨連絡人 | B18: AP8 劉韋智 | I18: 台灣積體電路製造股份有限公司 (FAB12B新竹 P4) | J18: 300新竹市東區園區二路168號
A19: 接貨人電話 | B19: #7553278 | I19: 台灣積體電路製造股份有限公司 (五廠 庫房) | J19: 300-77新竹科學園區園區三路121號
A20: PO NO. | B20: 4507489384 | I20: 台灣積體電路製造股份有限公司 (七廠 庫房) | J20: 300-77新竹科學工業園區研新二路6號 (1號碼頭)
A21: 55-0244 | C21: 長(L) | D21: 幅(W) | E21: 高(H) | F21: 數量 | G21: 重量 | H21: 車次 | I21: 揚發實業有限公司 | J21: 新北市林口區宏昌街86號
C22: (mm) | D22: (mm) | E22: (mm) | F22: (Set) | G22: (Tom) | H22: (輛) | I22: 台灣積體電路製造股份有限公司 (FAB12B新竹 P5) | J22: 300新竹市東區園區二路168號
A23: 物品名稱 | B23: KWE300-2P-FO-AL EFEM | C23: 2500 | D23: 120 | E23: 2300 | F23: 1 | G23: 1.8 | H23: 1 | I23: 台灣積體電路製造股份有限公司 (P6廠) | J23: 新竹縣寶山鄉新竹科學園區園區二路166號
I24: 台灣積體電路製造股份有限公司 (P7廠) | J24: 300新竹市東區科學園區園區二路188號
H25: =IF($B25=0," ",$H24+1) | I25: 台灣積體電路製造股份有限公司 | J25: 741台南市善化區環西路二段5號 (南科7路與南科7路間)
H26: =IF($B26=0," ",$H25+1) | I26: 台灣積體電路製造股份有限公司 (台積總部及晶圓十二A廠) | J26: 300-78 新竹科學工業園區力行六路8號
H27: =IF($B27=0," ",$H26+1) | I27: 台灣積體電路製造股份有限公司 (研發中心及晶圓十二B廠) | J27: 300-75 新竹科學工業園區園區二路168號
H28: =IF($B28=0," ",$H27+1) | I28: 台灣積體電路製造股份有限公司 (晶圓十四廠) | J28: 741-44 台南科學工業園區南科北路1號之1
H29: =IF($B29=0," ",$H28+1) | I29: 台灣積體電路製造股份有限公司 (晶圓十五廠) | J29: 428-82 中部科學工業園區科雅六路1號
H30: =IF($B30=0," ",$H29+1) | I30: 台灣積體電路製造股份有限公司 (晶圓十五廠 庫房) | J30: 428-82 中部科學工業園區科雅六路1號
H31: =IF($B31=0," ",$H30+1) | I31: 台灣積體電路製造股份有限公司 (FAB15B台中P5) | J31: 台中市大雅區科園2路 (中部科學園區)
H32: =IF($B32=0," ",$H31+1) | I32: 台灣積體電路製造股份有限公司 (FAB15B台中P6) | J32: 台中市大雅區科園2路 (中部科學園區)
H33: =IF($B33=0," ",$H32+1) | I33: 台灣積體電路製造股份有限公司 (晶圓三廠) | J33: 300-77 新竹科學工業園區研新一路9號
H34: =IF($B34=0," ",$H33+1) | I34: 台灣積體電路製造股份有限公司 (晶圓五廠) | J34: 300-77 新竹科學工業園區園區三路121號
H35: =IF($B35=0," ",$H34+1) | I35: 台灣積體電路製造股份有限公司 (晶圓六廠) | J35: 741-44 台南科學工業園區南科北路1號
H36: =IF($B36=0," ",$H35+1) | I36: 台灣積體電路製造股份有限公司 (晶圓八廠) | J36: 300-78 新竹科學工業園區力行路25號
... H40: =IF($B40=0," ",$H39+1) | I40: 台灣積體電路製造股份有限公司 (先進封測三廠) | J40: 325-42 桃園市龍潭區龍園六路101號
I41: 富元精密鍍膜股份有限公司 | J41: 桃園縣全區 平鎮市中興路平鎮段458號
I42: 友達光電總部 / 友達科技中心 / L3B 廠 | J42: 灣新竹市30078科學工業園區力行二路1號
I43: 新竹 L3A 廠 | J43: 臺灣新竹市30078科學工業園區力行六路5號
...

Sheet  出貨派車單
A1: 台灣平田機工股份有限公司
A2: 出貨派車單
A3: 專案代號 | B3: =CONCATENATE('派車單--資料寫入'!B2) -> 55-02137 | E3: 載貨數 | F3: 1
A4: 裝車日期 | B4: ='派車單--資料寫入'!B6 -> 46212 | E4: 裝車時間 | F4: ='派車單--資料寫入'!B7 -> 0.70833333
A5: 到貨日期 | B5: ='派車單--資料寫入'!B10 -> 46213 | E5: 到貨時間 | F5: ='派車單--資料寫入'!B11 -> 0.4375
A6: 客戶名稱 | B6: ='派車單--資料寫入'!B13 -> 台灣積體電路製造股份有限公司
A7: 出貨地 | B7: ='派車單--資料寫入'!B12 -> 台灣積體電路製造股份有限公司 AP8 台南市新市區環西路一段3號 | E7: R過磅 | F7: R客戶簽收單
F8: (取回-客戶簽收人的名片)
A9: 連絡人 | B9: ①接貨窗口： | D9: ②簽收窗口： | E9: =IF(COUNTIF($B6,"*1+1*"),"取回-客戶簽收人的名片"," ")
B10: =CONCATENATE('派車單--資料寫入'!$B18," ",'派車單--資料寫入'!$B19) -> AP8 劉韋智 #7553278 | D10: =CONCATENATE('派車單--資料寫入'!$B14," ",'派車單--資料寫入'!$B15) -> AP8 劉韋智 #7553278
A11: ='派車單--資料寫入'!B16 -> 310cm 低板 | B11: 司機: | E11: 填表人 | F11: Mei
A12: ='派車單--資料寫入'!B17 -> 共1輛 | B12: 車號 / 電話 : | F12: =TODAY() -> 46212
F13: 司機留存
F14: QP09-B
A16: 台灣平田機工股份有限公司
A17: 出貨派車單
A18: 專案代號 | B18: =B3 -> 55-02137 | E18: 載貨數 | F18: =F3 -> 1
A19: 裝車日期 | B19: =$B4 -> 46212 | E19: 裝車時間 | F19: =F4 -> 0.70833333
A20: 到貨日期 | B20: =$B5 -> 46213 | E20: 到貨時間 | F20: =F5 -> 0.4375
A21: 客戶名稱 | B21: =$B6 -> 台灣積體電路製造股份有限公司
A22: 出貨地 | B22: =$B7 -> 台灣積體電路製造股份有限公司 AP8 台南市新市區環西路一段3號 | E22: R過磅 | F22: R客戶簽收單
F23: =IF(F8=0," ",F8) -> (取回-客戶簽收人的名片)
A24: 連絡人 | B24: ①接貨窗口： | D24: ②簽收窗口： | E24: =E9
B25: =$B10 -> AP8 劉韋智 #7553278 | D25: =$D10 -> AP8 劉韋智 #7553278
A26: =A11 -> 310cm 低板 | B26: 司機: | E26: 填表人 | F26: =$F11 -> Mei
A27: =A12 -> 共1輛 | B27: 車號 / 電話 : | F27: =$F12 -> 46212
F28: 平田留存
F29: QP09-B

Sheet 機台上外面要的出貨標示
A1: 55-02137
A3: Tool ID. PO NO. | B3: Sponsor窗口 連絡電話 | C3: location ID
A4: 4507489384 | B4: 劉韋智 #7553278 | C4: APT DAF Curing POP-60A-PCFC

Sheet Packing List
A1: TAIWAN HIRATA CORPORATION
A2: No.128, Sec. 1, Sinwu Township, Taoyuan Hsien, Taiwan
A3: TEL: +886-3-477-7977 FAX:+ 886-3-477-7153 | D3: 製單人員: | E3: Mero
A4: 55-02137 送 貨 單
A5: 送貨地址: | B5: 台灣積體電路製造股份有限公司 AP8 台南市新市區環西路一段3號
A6: PO NO: | B6: 4507489384 | D6: 日期: | E6: 46212
A7: NO. | B7: Name | C7: Type | D7: Parts No. | E7: Quantity
A8: 1 | B8: KWE300-4P-FO-AL_APT(POP-60A-PCFC) | E8: 1 SET
B9: BK# A0J9W
B13: 以下空白
A28: 客戶回簽欄:
A29: 擔當窗口:
A30: AP8 劉韋智 #7553278
